
Status: FAILED!
Reason: Unable to run GuessNumber.py
Error: Traceback (most recent call last):
  File "/home/runner/work/9780357880876_pld-10e-python-8ddb5d1b-bece-4561-9ff4-f25ea7c30294/9780357880876_pld-10e-python-8ddb5d1b-bece-4561-9ff4-f25ea7c30294/GuessNumber.py", line 36, in <module>
    guessing_game()
  File "/home/runner/work/9780357880876_pld-10e-python-8ddb5d1b-bece-4561-9ff4-f25ea7c30294/9780357880876_pld-10e-python-8ddb5d1b-bece-4561-9ff4-f25ea7c30294/GuessNumber.py", line 25, in guessing_game
    again = input("Do you want to guess again? Enter Y or N: ").strip().upper()
EOFError: EOF when reading a line

Timestamp: 2024-10-16 16:07:07.186491

Status: FAILED!
Reason: Unable to run GuessNumber.py
Error: Traceback (most recent call last):
  File "/home/runner/work/9780357880876_pld-10e-python-8ddb5d1b-bece-4561-9ff4-f25ea7c30294/9780357880876_pld-10e-python-8ddb5d1b-bece-4561-9ff4-f25ea7c30294/GuessNumber.py", line 36, in <module>
    guessing_game()
  File "/home/runner/work/9780357880876_pld-10e-python-8ddb5d1b-bece-4561-9ff4-f25ea7c30294/9780357880876_pld-10e-python-8ddb5d1b-bece-4561-9ff4-f25ea7c30294/GuessNumber.py", line 25, in guessing_game
    again = input("Do you want to guess again? Enter Y or N: ").strip().upper()
EOFError: EOF when reading a line

Timestamp: 2024-10-16 16:07:07.186651

Status: FAILED!
Check: 2
Test: The program prompts the user to try again for incorrect input.
Reason: Unable to find '['Number must be in the range of 1 to 10: Please try again:']' in the program's output.
I'm thinking of a number...
Try to guess by entering a number between 1 and 10: Invalid input. Please enter a valid integer.
Try to guess by entering a number between 1 and 10: Invalid input. Please enter a number between 1 and 10.
Try to guess by entering a number between 1 and 10: Invalid input. Please enter a number between 1 and 10.
Try to guess by entering a number between 1 and 10: That's not correct. The correct number was 4.
Do you want to guess again? Enter Y or N: Thank you for playing!
.
Error : AssertionError - Unable to find Number must be in the range of 1 to 10: Please try again: in the program's output.
Timestamp: 2024-10-16 16:07:07.203981

Status: FAILED!
Check: 3
Test: The program generates a different random number for each run.
Reason: The correct number does not appear to be random.
Error : AssertionError - 
Timestamp: 2024-10-16 16:07:10.453103
